Workbook
Name Export_Data: #REF!
Name Export_Name: #REF!
Name Import_Data: #REF!
Name Import_Name: #REF!
Name Print_Area_MI: #REF!
Name Table1LinktoTop: #REF!
Name Table1Notes: #REF!
Name Use_Data: #REF!
Name Use_Names: #REF!

Sheet Index
A1: Vegetables and Pulses Yearbook Tables
A2: Sheet Names Hyperlinked Index | B2: Table Names
A3: =HYPERLINK("#'"&TableSheetNames!A3&"'!A1",TableSheetNames!A3) -> Table 1a-PerCapitaAvail,Major | B3: Table 1a--U.S. per capita availability of commercially produced, all utilizations vegetables and dry pulse crops by major commodity group
A4: =HYPERLINK("#'"&TableSheetNames!A4&"'!A1",TableSheetNames!A4) -> Table 1b-PerCapitaAvail,Minor | B4: Table 1b--U.S. per capita availability of commercially produced, all utilizations vegetables and dry pulse crops by commodity or commodity group
A5: =HYPERLINK("#'"&TableSheetNames!A5&"'!A1",TableSheetNames!A5) -> Table 2a-PerCapitaAvail, Fresh | B5: Table 2a--Vegetables, fresh market (including mushrooms): Selected U.S. per capita availability
A6: =HYPERLINK("#'"&TableSheetNames!A6&"'!A1",TableSheetNames!A6) -> Table 2b-PerCapitaAvail, Pr | B6: Table 2b--Vegetables, processing: Selected U.S. per capita availability
A7: =HYPERLINK("#'"&TableSheetNames!A7&"'!A1",TableSheetNames!A7) -> Table 2c-PerCapitaAvail, Potato | B7: Table 2c--Potatoes: U.S. per capita availability
A8: =HYPERLINK("#'"&TableSheetNames!A8&"'!A1",TableSheetNames!A8) -> Table 2d-PerCapitaAvail, Pulse | B8: Table 2d--Selected dry pulse crops: U.S. per capita availability
A9: =HYPERLINK("#'"&TableSheetNames!A9&"'!A1",TableSheetNames!A9) -> Table 3-Plant, Harvest, Prod | B9: Table 3--U.S. vegetable and dry pulse crop industry: Total harvested area, production, and crop value
A10: =HYPERLINK("#'"&TableSheetNames!A10&"'!A1",TableSheetNames!A10) -> Table 4a-Import Value | B10: Table 4a--Vegetable imports: U.S. value, by group, by month
A11: =HYPERLINK("#'"&TableSheetNames!A11&"'!A1",TableSheetNames!A11) -> Table 4b-Import Value | B11: Table 4b--Vegetable seed imports: U.S. value, by group, by month
A12: =HYPERLINK("#'"&TableSheetNames!A12&"'!A1",TableSheetNames!A12) -> Table 4c-Import Volume | B12: Table 4c--Vegetable imports: U.S. volume, by group, by month
A13: =HYPERLINK("#'"&TableSheetNames!A13&"'!A1",TableSheetNames!A13) -> Table 4d-Import Volume | B13: Table 4d--Vegetable seed imports: U.S. volume, by group, by month
A14: =HYPERLINK("#'"&TableSheetNames!A14&"'!A1",TableSheetNames!A14) -> Table 5a-Export Value | B14: Table 5a--Vegetable exports: U.S. value, by group, by month
... A101: =HYPERLINK("#'"&TableSheetNames!A101&"'!A1",TableSheetNames!A101) -> Table 72-Other | B101: Table 72--U.S. cranberry and other beans, dry: supply, availability, and price, farm weight
A102: Note: Cn = canned. Dehy = dehydrated. Fz = freezing. PerCapitaAvail = per capita availability. Pr = processing. Prod = production. Veg = vegetable.

Sheet TableSheetNames
A1: Sheet Names
A3: Table 1a-PerCapitaAvail,Major
A4: Table 1b-PerCapitaAvail,Minor
A5: Table 2a-PerCapitaAvail, Fresh
A6: Table 2b-PerCapitaAvail, Pr
A7: Table 2c-PerCapitaAvail, Potato
A8: Table 2d-PerCapitaAvail, Pulse
A9: Table 3-Plant, Harvest, Prod
A10: Table 4a-Import Value
A11: Table 4b-Import Value
A12: Table 4c-Import Volume
A13: Table 4d-Import Volume
... A101: Table 72-Other

Sheet Table 1a-PerCapitaAvail,Major
A1: Table 1a--U.S. per capita availability of commercially produced, all utilizations vegetables and dry pulse crops by major commodity group/1 | O1: =HYPERLINK("#'"&"Index'!A1","INDEX") -> INDEX
A2: Year | B2: Fresh vegetables/2 | C2: Processing vegetables/3 | D2: Potatoes/4 | E2: Dry pulses/5 | F2: Mushrooms/6 | G2: Total vegetables and pulses
A3: 1980 | B3: 99.593 | C3: 116.619 | D3: 114.754 | E3: 5.995 | F3: 2.881 | G3: 339.842
A4: 1981 | B4: 98.481 | C4: 111.96 | D4: 116.517 | E4: 5.938 | F4: 2.739 | G4: 335.635
A5: 1982 | B5: 102.98 | C5: 109.777 | D5: 115.023 | E5: 7.691 | F5: 2.927 | G5: 338.398
A6: 1983 | B6: 100.564 | C6: 111.712 | D6: 118.639 | E6: 6.666 | F6: 2.968 | G6: 340.549
A7: 1984 | B7: 107.282 | C7: 119.694 | D7: 122.095 | E7: 5.836 | F7: 3.468 | G7: 358.375
A8: 1985 | B8: 111.16 | C8: 116.197 | D8: 122.402 | E8: 7.356 | F8: 3.542 | G8: 360.657
A9: 1986 | B9: 108.622 | C9: 116.239 | D9: 125.945 | E9: 7.062 | F9: 3.604 | G9: 361.472
A10: 1987 | B10: 118.983 | C10: 116.3 | D10: 125.964 | E10: 5.963 | F10: 3.782 | G10: 370.992
A11: 1988 | B11: 123.353 | C11: 114.067 | D11: 122.389 | E11: 7.548 | F11: 3.586 | G11: 370.943
A12: 1989 | B12: 128.937 | C12: 119.997 | D12: 126.997 | E12: 6.037 | F12: 3.544 | G12: 385.512
A13: 1990 | B13: 127.662 | C13: 129.595 | D13: 124 | E13: 7.195 | F13: 3.592 | G13: 392.044
A14: 1991 | B14: 124.063 | C14: 131.952 | D14: 133.956 | E14: 7.907 | F14: 3.716 | G14: 401.594
... A47: 2024 | B47: 147.669 | C47: 95.172 | D47: 116.296 | E47: 11.069 | F47: 3.314 | G47: 373.52
A48: Note: Most recent year is preliminary. Totals may not sum due to rounding.
A49: 1/ Unit of measure is pounds per person.
A50: 2/ Fresh vegetable availability includes all commodities and uses identified in table 2a excluding fresh mushrooms.
A51: 3/ Processing vegetable availability includes all commodities and uses identified in table 2b excluding processing mushrooms.
A52: 4/ Potato availability includes all potato uses identified in table 2c.
A53: 5/ Dry pulses availability includes all pulse types identified in table 2d.
A54: 6/ Mushroom availability includes both fresh and processing identified in tables 28 and 51.
A55: Source: USDA, Economic Research Service.

Sheet Table 1b-PerCapitaAvail,Minor
A1: Table 1b--U.S. per capita availability of commercially produced, all utilizations vegetables and dry pulse crops by commodity or commodity group/1 | O1: =HYPERLINK("#'"&"Index'!A1","INDEX") -> INDEX
A2: Year | B2: Artichokes (all uses) | C2: Asparagus (fresh and processing) | D2: Beans, lima green (fresh and processing) | E2: Beans, snap green (fresh and processing) | F2: Beets (processing) | G2: Black beans (dry) | H2: Blackeye beans (dry) | I2: Broccoli (fresh and processing) | J2: Brussels sprouts (fresh) | K2: Cabbage (fresh and processing) | L2: Carrots (fresh and processing) | M2: Cauliflower (fresh and processing) | N2: Celery (all uses) | O2: Chickpea/garbanzo (fresh and processing) | P2: Cucumbers (fresh and processing) | Q2: Dry peas and lentils (dry) | R2: Eggplant (all uses) | S2: Escarole and endive (fresh) | T2: Garlic (all uses) | U2: Great Northern beans (dry) | V2: Greens, collard (fresh) | W2: Greens, mustard (fresh) | X2: Greens, turnip (fresh) | Y2: Kale (fresh) | Z2: Lettuce, head/iceberg (fresh) | AA2: Lettuce, leaf and romaine (fresh) | AB2: Lima beans (dry) | AC2: Mushrooms (fresh and processing) | AD2: Navy beans (dry) | AE2: Okra (fresh) | AF2: Onions (fresh and processing) | AG2: Other unspecified beans including cranberry (dry) | AH2: Other, processing/2 | AI2: Peas, green (processing) | AJ2: Peppers, bell (fresh) | AK2: Peppers, chili (fresh) | AL2: Pink beans (dry) | AM2: Pinto beans (dry) | AN2: Potatoes (fresh and processing) | AO2: Pumpkins (all uses) | AP2: Radishes (all uses) | AQ2: Red kidney beans (dry) | AR2: Small red beans (dry) | AS2: Small white beans (dry) | AT2: Spinach (fresh and processing) | AU2: Squash (all uses) | AV2: Sweet corn (fresh and processing) | AW2: Sweet potatoes (all uses) | AX2: Tomatoes (fresh and processing) | AY2: Total vegetables and pulses (all uses)
A3: 1980 | B3: 0.58710907 | C3: 0.78546823 | D3: 1.3004049 | E3: 7.2317257 | F3: 1.8196923 | G3: 0.0059707719 | H3: 0.22893531 | I3: 2.8563294 | J3: 0.28543074 | K3: 9.9829067 | L3: 9.6244576 | M3: 1.9162554 | N3: 7.371644 | O3: 0.14290476 | P3: 9.259197 | Q3: 0.59898581 | R3: 0.47732802 | S3: 0.45141969 | T3: 0.86089423 | U3: 0.4135865 | V3: NA | W3: NA | X3: NA | Y3: NA | Z3: 25.745413 | AA3: NA | AB3: 0.30642137 | AC3: 2.881426 | AD3: 2.0068635 | AE3: 0.31082629 | AF3: 12.153255 | AG3: 0.68547289 | AH3: 1.4605271 | AI3: 4.4666446 | AJ3: 2.8854852 | AK3: 3.0490414 | AL3: 0.19247469 | AM3: 0.79197193 | AN3: 114.75343 | AO3: NA | AP3: 0.56509849 | AQ3: 0.49373739 | AR3: 0.1022271 | AS3: 0.025599078 | AT3: 1.8067498 | AU3: 2.307953 | AV3: 25.931497 | AW3: 4.3867077 | AX3: 76.982528 | AY3: 340.492
A4: 1981 | B4: 0.7475018 | C4: 0.79570541 | D4: 1.3804475 | E4: 7.5634999 | F4: 1.6143636 | G4: 0.070927876 | H4: 0.19408098 | I4: 3.220572 | J4: 0.363532 | K4: 10.179022 | L4: 9.5640272 | M4: 2.2777603 | N4: 7.2720054 | O4: 0.14685195 | P4: 9.3432796 | Q4: 0.51639989 | R4: 0.45832862 | S4: 0.44310898 | T4: 0.65922789 | U4: 0.28968178 | V4: NA | W4: NA | X4: NA | Y4: NA | Z4: 25.028482 | AA4: NA | AB4: 0.28250015 | AC4: 2.7390743 | AD4: 1.1464521 | AE4: 0.34366901 | AF4: 11.555312 | AG4: 0.41745301 | AH4: 1.5658837 | AI4: 4.43424 | AJ4: 2.786064 | AK4: 3.2675569 | AL4: 0.38674933 | AM4: 1.9816298 | AN4: 116.51684 | AO4: NA | AP4: 0.57450824 | AQ4: 0.31195716 | AR4: 0.15692452 | AS4: 0.035967651 | AT4: 1.7925976 | AU4: 2.3248561 | AV4: 24.648956 | AW4: 4.6715368 | AX4: 72.255274 | AY4: 336.32481
A5: 1982 | B5: 0.82303995 | C5: 0.72078912 | D5: 1.1410202 | E5: 6.9901009 | F5: 1.3451255 | G5: 0.043411374 | H5: 0.29001193 | I5: 3.5035912 | J5: 0.31956863 | K5: 10.253895 | L5: 9.5446119 | M5: 2.221161 | N5: 7.4119377 | O5: 0.11063183 | P5: 9.2929117 | Q5: 0.34396106 | R5: 0.51380778 | S5: 0.37728048 | T5: 0.75717953 | U5: 0.49405826 | V5: NA | W5: NA | X5: NA | Y5: NA | Z5: 25.023688 | AA5: NA | AB5: 0.34482216 | AC5: 2.927171 | AD5: 1.5579453 | AE5: 0.3157615 | AF5: 14.248509 | AG5: 0.26357951 | AH5: 1.5543439 | AI5: 4.1380077 | AJ5: 2.9721605 | AK5: 3.0546195 | AL5: 0.32950309 | AM5: 3.270771 | AN5: 115.02323 | AO5: NA | AP5: 0.50078349 | AQ5: 0.51535799 | AR5: 0.061328631 | AS5: 0.065378991 | AT5: 1.6757272 | AU5: 2.4567936 | AV5: 23.365937 | AW5: 5.3925603 | AX5: 73.41164 | AY5: 338.96771
A6: 1983 | B6: 0.73450644 | C6: 0.83826996 | D6: 0.9305415 | E6: 6.7793739 | F6: 1.2579724 | G6: 0.032917497 | H6: 0.26371152 | I6: 3.5988484 | J6: 0.29363186 | K6: 10.284658 | L6: 9.5383434 | M6: 2.2626989 | N6: 7.0013145 | O6: 0.13974955 | P6: 9.6924205 | Q6: 0.4186865 | R6: 0.51257538 | S6: 0.39478121 | T6: 0.9974606 | U6: 0.44604318 | V6: NA | W6: NA | X6: NA | Y6: NA | Z6: 22.524722 | AA6: NA | AB6: 0.27923794 | AC6: 2.9683079 | AD6: 1.6027554 | AE6: 0.45284079 | AF6: 13.822478 | AG6: 0.29107112 | AH6: 1.633754 | AI6: 4.2113234 | AJ6: 3.3255515 | AK6: 3.3093762 | AL6: 0.13710364 | AM6: 2.3524948 | AN6: 118.63891 | AO6: NA | AP6: 0.54659463 | AQ6: 0.53040404 | AR6: 0.097414516 | AS6: 0.074684315 | AT6: 1.6000872 | AU6: 2.5561191 | AV6: 24.417772 | AW6: 4.4851946 | AX6: 74.737968 | AY6: 341.01467
A7: 1984 | B7: 0.95452468 | C7: 0.81210634 | D7: 1.3647081 | E7: 6.8339595 | F7: 1.2442764 | G7: 0.02022103 | H7: 0.20605832 | I7: 4.2009889 | J7: 0.30675106 | K7: 10.265262 | L7: 10.664557 | M7: 2.7742211 | N7: 7.1150465 | O7: 0.10031793 | P7: 9.8802505 | Q7: 0.42888967 | R7: 0.46880024 | S7: 0.387141 | T7: 0.76888317 | U7: 0.48743717 | V7: NA | W7: NA | X7: NA | Y7: NA | Z7: 24.988999 | AA7: NA | AB7: 0.30701731 | AC7: 3.4680385 | AD7: 1.7217116 | AE7: 0.44552063 | AF7: 14.560113 | AG7: 0.20435967 | AH7: 1.3725523 | AI7: 4.0274449 | AJ7: 3.6247398 | AK7: 3.6141537 | AL7: 0.053137278 | AM7: 1.6965772 | AN7: 122.09527 | AO7: NA | AP7: 0.49504744 | AQ7: 0.35391203 | AR7: 0.039505347 | AS7: 0.21705529 | AT7: 1.3631699 | AU7: 2.6249691 | AV7: 24.638804 | AW7: 4.8320822 | AX7: 83.030233 | AY7: 359.05881
A8: 1985 | B8: 1.0227873 | C8: 0.86256047 | D8: 1.1449959 | E8: 6.8899835 | F8: 0.87434582 | G8: 0.012876049 | H8: 0.22823964 | I8: 4.5398526 | J8: 0.32876804 | K8: 10.32959 | L8: 9.6610023 | M8: 2.7673772 | N8: 6.8803519 | O8: 0.071852689 | P8: 10.2198 | Q8: 0.44383669 | R8: 0.45792692 | S8: 0.38915401 | T8: 1.0616188 | U8: 0.47081865 | V8: NA | W8: NA | X8: NA | Y8: NA | Z8: 23.750975 | AA8: 3.265455 | AB8: 0.36763258 | AC8: 3.541953 | AD8: 1.8513079 | AE8: 0.38268726 | AF8: 15.196806 | AG8: 0.23106019 | AH8: 1.3913933 | AI8: 4.1433268 | AJ8: 3.8001224 | AK8: 3.910612 | AL8: 0.099011588 | AM8: 2.7736421 | AN8: 122.40229 | AO8: NA | AP8: 0.51205497 | AQ8: 0.45248639 | AR8: 0.050460064 | AS8: 0.30251565 | AT8: 1.7230376 | AU8: 2.6724221 | AV8: 26.207508 | AW8: 5.2604073 | AX8: 78.287106 | AY8: 361.23401
A9: 1986 | B9: 0.93537945 | C9: 0.99025963 | D9: 1.1909146 | E9: 6.6347342 | F9: 1.0610853 | G9: 0.031182085 | H9: 0.19426848 | I9: 4.8314249 | J9: 0.32661406 | K9: 10.191561 | L9: 9.465912 | M9: 3.1111565 | N9: 6.4927634 | O9: 0.093016273 | P9: 9.9508811 | Q9: 0.70291094 | R9: 0.46665088 | S9: 0.36609031 | T9: 0.7660471 | U9: 0.46614292 | V9: NA | W9: NA | X9: NA | Y9: NA | Z9: 22.007804 | AA9: 2.3735617 | AB9: 0.34858855 | AC9: 3.6035972 | AD9: 1.1888253 | AE9: 0.28527349 | AF9: 15.626765 | AG9: 0.30625262 | AH9: 1.6255906 | AI9: 4.0799128 | AJ9: 3.9654936 | AK9: 4.1749172 | AL9: 0.30487625 | AM9: 2.6275426 | AN9: 125.94605 | AO9: NA | AP9: 0.46356455 | AQ9: 0.50566173 | AR9: 0.16001704 | AS9: 0.13178686 | AT9: 1.4836156 | AU9: 2.775282 | AV9: 25.706652 | AW9: 4.2620809 | AX9: 79.843084 | AY9: 362.06579
A10: 1987 | B10: 0.99298199 | C10: 0.9470657 | D10: 1.0777447 | E10: 6.6506326 | F10: 0.76173066 | G10: 0.049285844 | H10: 0.23420233 | I10: 5.3034588 | J10: 0.25864483 | K10: 10.688579 | L10: 11.437094 | M10: 3.077091 | N10: 6.5935734 | O10: 0.10066382 | P10: 10.601884 | Q10: 0.57932702 | R10: 0.47280934 | S10: 0.34142765 | T10: 1.187501 | U10: 0.20494555 | V10: NA | W10: NA | X10: NA | Y10: NA | Z10: 25.796527 | AA10: 2.5246701 | AB10: 0.18291659 | AC10: 3.7815963 | AD10: 1.4407872 | AE10: 0.21370764 | AF10: 14.930119 | AG10: 0.1915125 | AH10: 1.5872885 | AI10: 3.7311688 | AJ10: 4.2293372 | AK10: 4.1653638 | AL10: 0.18311744 | AM10: 2.2505568 | AN10: 125.96359 | AO10: 3.0136901 | AP10: 0.51295693 | AQ10: 0.36922415 | AR10: 0.077182672 | AS10: 0.099068216 | AT10: 1.3575154 | AU10: 2.8793512 | AV10: 24.731517 | AW10: 4.3022853 | AX10: 81.453764 | AY10: 371.52946
A11: 1988 | B11: 0.91461548 | C11: 1.0374863 | D11: 0.86427502 | E11: 6.6923982 | F11: 0.88849527 | G11: 0.0097922219 | H11: 0.35295957 | I11: 6.1898858 | J11: 0.25589643 | K11: 10.441079 | L11: 10.453272 | M11: 3.1380167 | N11: 7.1528563 | O11: 0.13342237 | P11: 10.103129 | Q11: 0.70132501 | R11: 0.39017064 | S11: 0.35752038 | T11: 1.0862824 | U11: 0.54492472 | V11: NA | W11: NA | X11: NA | Y11: NA | Z11: 27.167467 | AA11: 3.200542 | AB11: 0.19852384 | AC11: 3.5859676 | AD11: 1.1190518 | AE11: 0.41480809 | AF11: 16.216632 | AG11: 0.29344424 | AH11: 2.0137049 | AI11: 3.6565375 | AJ11: 4.4755348 | AK11: 4.3147526 | AL11: 0.19767824 | AM11: 3.3391273 | AN11: 122.38942 | AO11: 3.8059173 | AP11: 0.54979865 | AQ11: 0.32100391 | AR11: 0.099355173 | AS11: 0.23743809 | AT11: 1.5232961 | AU11: 3.0774864 | AV11: 24.919327 | AW11: 3.9309917 | AX11: 78.618006 | AY11: 371.37361
A12: 1989 | B12: 0.97436828 | C12: 0.95084498 | D12: 0.7860221 | E12: 7.0745135 | F12: 0.81506578 | G12: 0.06404385 | H12: 0.30017747 | I12: 5.9729584 | J12: 0.33678065 | K12: 9.8856973 | L12: 11.469962 | M12: 3.0623994 | N12: 7.4742664 | O12: 0.12506322 | P12: 9.9740369 | Q12: 0.61755996 | R12: 0.39904262 | S12: 0.33022532 | T12: 1.0146194 | U12: 0.44334889 | V12: NA | W12: NA | X12: NA | Y12: NA | Z12: 28.685383 | AA12: 3.563487 | AB12: 0.29813705 | AC12: 3.5437935 | AD12: 1.0607467 | AE12: 0.43835044 | AF12: 16.376521 | AG12: 0.21306531 | AH12: 1.8480485 | AI12: 3.710079 | AJ12: 4.6885731 | AK12: 4.5038993 | AL12: 0.071244211 | AM12: 2.125595 | AN12: 126.9976 | AO12: 4.8200063 | AP12: 0.707875 | AQ12: 0.40413759 | AR12: 0.16897393 | AS12: 0.14508402 | AT12: 1.4131079 | AU12: 3.4519138 | AV12: 24.434181 | AW12: 3.9246786 | AX12: 86.240714 | AY12: 385.90619
A13: 1990 | B13: 0.84581544 | C13: 1.0060941 | D13: 0.67902819 | E13: 6.7009817 | F13: 0.85514848 | G13: 0.10049336 | H13: 0.26767867 | I13: 5.6007652 | J13: 0.31703261 | K13: 9.5307934 | L13: 12.376207 | M13: 2.9486189 | N13: 7.1944573 | O13: 0.10435605 | P13: 9.6682207 | Q13: 0.46645409 | R13: 0.39938912 | S13: 0.26232847 | T13: 1.4071459 | U13: 0.3632642 | V13: NA | W13: NA | X13: NA | Y13: NA | Z13: 27.746879 | AA13: 3.7702632 | AB13: 0.24055899 | AC13: 3.5915714 | AD13: 1.2587786 | AE13: 0.24350829 | AF13: 17.194251 | AG13: 0.2306782 | AH13: 2.5320449 | AI13: 4.1620932 | AJ13: 5.8810651 | AK13: 4.8310338 | AL13: 0.25642564 | AM13: 3.0750962 | AN13: 123.99975 | AO13: 4.4334634 | AP13: 0.65856476 | AQ13: 0.59251507 | AR13: 0.12315101 | AS13: 0.11675594 | AT13: 1.3211155 | AU13: 3.5056748 | AV13: 26.289875 | AW13: 4.3992863 | AX13: 90.835762 | AY13: 392.38443
A14: 1991 | B14: 0.8268557 | C14: 0.96879545 | D14: 0.81754388 | E14: 6.9893316 | F14: 0.76017878 | G14: 0.14541927 | H14: 0.27509635 | I14: 5.2949199 | J14: 0.29902206 | K14: 9.6392773 | L14: 11.280566 | M14: 2.5333603 | N14: 6.7326987 | O14: 0.10611894 | P14: 9.6137997 | Q14: 0.55979746 | R14: 0.4114512 | S14: 0.24675195 | T14: 1.4871594 | U14: 0.49515529 | V14: NA | W14: NA | X14: NA | Y14: NA | Z14: 26.044844 | AA14: 3.9967137 | AB14: 0.24744567 | AC14: 3.7157235 | AD14: 1.4667166 | AE14: 0.24635167 | AF14: 17.258669 | AG14: 0.27890316 | AH14: 2.890139 | AI14: 4.1544665 | AJ14: 6.3012046 | AK14: 4.5134084 | AL14: 0.22017345 | AM14: 3.2821338 | AN14: 133.95551 | AO14: 4.4291907 | AP14: 0.54758981 | AQ14: 0.54057953 | AR14: 0.17276875 | AS14: 0.11671433 | AT14: 1.7982879 | AU14: 3.6718586 | AV14: 26.332843 | AW14: 3.8666558 | AX14: 92.470101 | AY14: 402.00229
A15: 1992 | B15: 0.87886863 | C15: 0.98859235 | D15: 0.94734576 | E15: 7.1639277 | F15: 0.91648696 | G15: 0.13853639 | H15: 0.28917678 | I15: 5.798692 | J15: 0.28221757 | K15: 9.8106257 | L15: 12.322738 | M15: 2.4634717 | N15: 7.3233586 | O15: 0.10185251 | P15: 9.47319 | Q15: 0.55897747 | R15: 0.46984359 | S15: 0.32000233 | T15: 1.4605521 | U15: 0.48550453 | V15: NA | W15: NA | X15: NA | Y15: NA | Z15: 25.790598 | AA15: 4.6696133 | AB15: 0.21924814 | AC15: 3.6813101 | AD15: 1.5362009 | AE15: 0.28337809 | AF15: 17.536673 | AG15: 0.42235319 | AH15: 2.4029678 | AI15: 4.0921547 | AJ15: 7.1018735 | AK15: 5.5822789 | AL15: 0.16387576 | AM15: 3.7883098 | AN15: 129.79711 | AO15: 4.0575383 | AP15: 0.4763766 | AQ15: 0.55886236 | AR15: 0.044491724 | AS15: 0.070323624 | AT15: 1.6269109 | AU15: 3.8059271 | AV15: 27.664175 | AW15: 4.0755863 | AX15: 88.761424 | AY15: 400.40352
A16: 1993 | B16: 0.86383358 | C16: 0.90918178 | D16: 0.86467343 | E16: 7.2117532 | F16: 0.83156904 | G16: 0.2075423 | H16: 0.24291152 | I16: 5.6043661 | J16: 0.34773587 | K16: 10.675451 | L16: 14.679961 | M16: 2.7783993 | N16: 7.2613997 | O16: 0.18360205 | P16: 9.5392824 | Q16: 0.5107358 | R16: 0.47146068 | S16: 0.30049785 | T16: 1.7456097 | U16: 0.4197514 | V16: NA | W16: NA | X16: NA | Y16: NA | Z16: 24.400035 | AA16: 5.0417061 | AB16: 0.22232974 | AC16: 3.6913502 | AD16: 1.2012849 | AE16: 0.3836143 | AF16: 19.166069 | AG16: 0.20672033 | AH16: 2.961367 | AI16: 3.4501031 | AJ16: 7.6309872 | AK16: 4.8971287 | AL16: 0.18240878 | AM16: 3.5489506 | AN16: 136.48924 | AO16: 5.1255779 | AP16: 0.51680086 | AQ16: 0.58491948 | AR16: 0.18557529 | AS16: 0.040344157 | AT16: 1.6686664 | AU16: 3.7846051 | AV16: 27.77307 | AW16: 3.6597012 | AX16: 92.07806 | AY16: 414.54033
A17: 1994 | B17: 1.2662966 | C17: 0.93530656 | D17: 0.96030422 | E17: 7.2691216 | F17: 1.1359116 | G17: 0.300676 | H17: 0.27944102 | I17: 6.7392852 | J17: 0.32379781 | K17: 10.307769 | L17: 16.90518 | M17: 2.6086002 | N17: 7.2366347 | O17: 0.16360481 | P17: 10.142108 | Q17: 0.44131233 | R17: 0.51625442 | S17: 0.3288263 | T17: 1.7971356 | U17: 0.35100105 | V17: NA | W17: NA | X17: NA | Y17: NA | Z17: 25.00662 | AA17: 5.6782245 | AB17: 0.19367947 | AC17: 3.7264672 | AD17: 1.8361925 | AE17: 0.24312568 | AF17: 17.86299 | AG17: 0.30595666 | AH17: 2.9391305 | AI17: 3.5722487 | AJ17: 7.0592418 | AK17: 4.1043643 | AL17: 0.21391668 | AM17: 3.3081968 | AN17: 136.46112 | AO17: 5.4914158 | AP17: 0.43575459 | AQ17: 0.61170082 | AR17: 0.11952528 | AS17: 0.024517909 | AT17: 1.71204 | AU17: 3.9297531 | AV17: 27.330661 | AW17: 4.462573 | AX17: 92.492958 | AY17: 419.13094
A18: 1995 | B18: 0.92478362 | C18: 0.89925542 | D18: 1.1346056 | E18: 6.8286681 | F18: 1.1254628 | G18: 0.42617689 | H18: 0.26343629 | I18: 6.8569003 | J18: 0.33501277 | K18: 9.4955639 | L18: 15.403302 | M18: 2.2439114 | N18: 6.9344657 | O18: 0.13369336 | P18: 10.654943 | Q18: 0.95085493 | R18: 0.4726944 | S18: 0.30408034 | T18: 1.8497981 | U18: 0.36258184 | V18: NA | W18: NA | X18: NA | Y18: NA | Z18: 22.167103 | AA18: 5.8945453 | AB18: 0.23648659 | AC18: 4.0611014 | AD18: 1.6487236 | AE18: 0.38204529 | AF18: 19.102666 | AG18: 0.29562157 | AH18: 2.6424177 | AI18: 3.6375219 | AJ18: 7.0105234 | AK18: 3.8340742 | AL18: 0.17627711 | AM18: 3.2187791 | AN18: 136.62411 | AO18: 5.8963229 | AP18: 0.41383618 | AQ18: 0.5613297 | AR18: 0.13645069 | AS18: 0.046266134 | AT18: 1.6583817 | AU18: 3.7457673 | AV18: 28.560595 | AW18: 4.2075966 | AX18: 91.405199 | AY18: 415.16393
A19: 1996 | B19: 0.98941365 | C19: 0.91194311 | D19: 1.1629401 | E19: 7.2049385 | F19: 0.93352171 | G19: 0.3560823 | H19: 0.25701865 | I19: 7.0349565 | J19: 0.3304075 | K19: 9.2467854 | L19: 16.924301 | M19: 2.2002083 | N19: 7.0272566 | O19: 0.25927014 | P19: 10.006672 | Q19: 0.6496202 | R19: 0.59888678 | S19: 0.31911182 | T19: 2.2946341 | U19: 0.54026556 | V19: NA | W19: NA | X19: NA | Y19: NA | Z19: 21.574936 | AA19: 5.8176096 | AB19: 0.19952012 | AC19: 3.7821425 | AD19: 1.2668872 | AE19: 0.33671025 | AF19: 19.164961 | AG19: 0.24140885 | AH19: 2.7990299 | AI19: 3.396385 | AJ19: 8.0689195 | AK19: 4.7303682 | AL19: 0.14501215 | AM19: 3.3991545 | AN19: 144.8891 | AO19: 5.7748518 | AP19: 0.4070195 | AQ19: 0.55238403 | AR19: 0.16572879 | AS19: 0.051996288 | AT19: 1.7684161 | AU19: 3.689598 | AV19: 29.037586 | AW19: 4.2873826 | AX19: 90.849866 | AY19: 425.64521
A20: 1997 | B20: 1.0097108 | C20: 0.93754797 | D20: 1.1059849 | E20: 6.7388561 | F20: 0.89406109 | G20: 0.33622026 | H20: 0.23822376 | I20: 7.2487319 | J20: 0.24769889 | K20: 10.449814 | L20: 18.162089 | M20: 2.2006904 | N20: 6.5491764 | O20: 0.2441772 | P20: 11.658628 | Q20: 0.89886315 | R20: 0.65016379 | S20: 0.29943237 | T20: 1.9951143 | U20: 0.39961737 | V20: 0.79496688 | W20: 0.68184323 | X20: 0.52824354 | Y20: 0.42355411 | Z20: 23.901619 | AA20: 6.5947438 | AB20: 0.2095174 | AC20: 3.9276834 | AD20: 1.3732881 | AE20: 0.23038354 | AF20: 19.732785 | AG20: 0.18137715 | AH20: 2.6805175 | AI20: 3.4983958 | AJ20: 7.333958 | AK20: 4.5860384 | AL20: 0.20298074 | AM20: 3.474068 | AN20: 137.71126 | AO20: 5.6483839 | AP20: 0.50624526 | AQ20: 0.54476488 | AR20: 0.14483121 | AS20: 0.047534363 | AT20: 1.9252052 | AU20: 3.8504536 | AV20: 27.497253 | AW20: 4.260937 | AX20: 89.867085 | AY20: 424.62471
A21: 1998 | B21: 1.179916 | C21: 0.97956756 | D21: 1.0733064 | E21: 7.3401245 | F21: 0.74990493 | G21: 0.52565659 | H21: 0.21916083 | I21: 7.1241326 | J21: 0.28140449 | K21: 9.8099372 | L21: 13.735433 | M21: 2.2333696 | N21: 6.4673904 | O21: 0.16308539 | P21: 10.502961 | Q21: 0.80174557 | R21: 0.69975191 | S21: 0.30421735 | T21: 2.5842585 | U21: 0.35309078 | V21: 0.78734585 | W21: 0.68503167 | X21: 0.5147913 | Y21: 0.40420875 | Z21: 22.324952 | AA21: 6.614551 | AB21: 0.21445999 | AC21: 3.991809 | AD21: 1.1104224 | AE21: 0.28518904 | AF21: 19.49434 | AG21: 0.16 | AH21: 2.7309749 | AI21: 3.3404476 | AJ21: 7.7627909 | AK21: 4.7581953 | AL21: 0.21040282 | AM21: 3.441908 | AN21: 137.55073 | AO21: 6.3565421 | AP21: 0.44469635 | AQ21: 0.61237 | AR21: 0.20964536 | AS21: 0.038667309 | AT21: 1.7468997 | AU21: 4.1602632 | AV21: 28.340068 | AW21: 3.8476933 | AX21: 92.526774 | AY21: 421.79459
A22: 1999 | B22: 1.3208194 | C22: 1.123902 | D22: 1.0223257 | E22: 7.5269341 | F22: 0.83925598 | G22: 0.61909061 | H22: 0.25031071 | I22: 8.2702862 | J22: 0.25779194 | K22: 8.7888492 | L22: 13.070633 | M22: 2.2673975 | N22: 6.5317241 | O22: 0.15935476 | P22: 10.931359 | Q22: 0.57943197 | R22: 0.6660198 | S22: 0.22510256 | T22: 3.2924124 | U22: 0.53294175 | V22: 0.77996384 | W22: 0.68820366 | X22: 0.5139323 | Y22: 0.3853388 | Z22: 24.909064 | AA22: 7.5915765 | AB22: 0.2099456 | AC22: 3.8685256 | AD22: 1.2231847 | AE22: 0.27126852 | AF22: 20.732694 | AG22: 0.24597648 | AH22: 3.8024772 | AI22: 3.4496217 | AJ22: 7.7191554 | AK22: 4.7045733 | AL22: 0.27590925 | AM22: 3.4587234 | AN22: 136.15684 | AO22: 5.9205161 | AP22: 0.39181833 | AQ22: 0.58217205 | AR22: 0.22057936 | AS22: 0.023721531 | AT22: 1.8234045 | AU22: 4.0979396 | AV22: 28.237925 | AW22: 3.7182722 | AX22: 90.253098 | AY22: 424.53236
A23: 2000 | B23: 1.2417402 | C23: 1.2524692 | D23: 1.0771679 | E23: 7.8626935 | F23: 0.8014602 | G23: 0.63750711 | H23: 0.22138513 | I23: 8.1418316 | J23: 0.28310671 | K23: 10.273098 | L23: 12.992484 | M23: 2.3004939 | N23: 6.2689816 | O23: 0.41241622 | P23: 11.243334 | Q23: 0.91088496 | R23: 0.80699224 | S23: 0.34464491 | T23: 2.2203011 | U23: 0.47028971 | V23: 0.77299547 | W23: 0.73493192 | X23: 0.51525477 | Y23: 0.38471754 | Z23: 23.460663 | AA23: 8.3850164 | AB23: 0.17769382 | AC23: 4.0718351 | AD23: 1.1629528 | AE23: 0.21457933 | AF23: 20.43121 | AG23: 0.33323349 | AH23: 3.4896983 | AI23: 3.6744645 | AJ23: 8.1856582 | AK23: 5.1535461 | AL23: 0.15247924 | AM23: 3.4653147 | AN23: 138.00733 | AO23: 4.5988917 | AP23: 0.48062262 | AQ23: 0.49039295 | AR23: 0.13449 | AS23: 0.025113936 | AT23: 2.4477887 | AU23: 4.4308357 | AV23: 27.09017 | AW23: 4.2046242 | AX23: 89.124123 | AY23: 425.56392
A24: 2001 | B24: 1.229626 | C24: 1.2044382 | D24: 0.8671286 | E24: 7.8309002 | F24: 0.77936548 | G24: 0.56352091 | H24: 0.22151976 | I24: 7.4366247 | J24: 0.22985233 | K24: 10.091556 | L24: 12.73594 | M24: 2.0210956 | N24: 6.4123287 | O24: 0.35518163 | P24: 10.001275 | Q24: 0.71003829 | R24: 0.83239202 | S24: 0.35020843 | T24: 2.4156995 | U24: 0.44883077 | V24: 0.7666214 | W24: 0.78110058 | X24: 0.41498863 | Y24: 0.36680719 | Z24: 22.988083 | AA24: 8.0272375 | AB24: 0.21559928 | AC24: 4.0819029 | AD24: 1.0009821 | AE24: 0.27470434 | AF24: 19.505 | AG24: 0.25656392 | AH24: 4.3535777 | AI24: 3.3350569 | AJ24: 8.119456 | AK24: 5.1788425 | AL24: 0.093859412 | AM24: 3.2283475 | AN24: 138.7317 | AO24: 4.1023444 | AP24: 0.5075386 | AQ24: 0.52891682 | AR24: 0.11766803 | AS24: 0.010693855 | AT24: 1.9186483 | AU24: 4.1968831 | AV24: 27.1566 | AW24: 4.3690055 | AX24: 84.732656 | AY24: 416.09891
A25: 2002 | B25: 1.3238016 | C25: 1.2429903 | D25: 1.0285467 | E25: 7.2120935 | F25: 0.46664961 | G25: 0.52752045 | H25: 0.1835105 | I25: 7.4487127 | J25: 0.20080839 | K25: 9.4731648 | L25: 11.517709 | M25: 1.7280266 | N25: 6.3019613 | O25: 0.27827588 | P25: 12.027469 | Q25: 0.99883919 | R25: 0.71906532 | S25: 0.3097366 | T25: 2.4999251 | U25: 0.35861638 | V25: 0.76034596 | W25: 0.69869756 | X25: 0.45786114 | Y25: 0.34571388 | Z25: 22.542564 | AA25: 9.5939436 | AB25: 0.14297448 | AC25: 3.9330662 | AD25: 0.90269636 | AE25: 0.22404751 | AF25: 20.402904 | AG25: 0.45573691 | AH25: 5.5975739 | AI25: 2.7960349 | AJ25: 8.2645699 | AK25: 5.8265534 | AL25: 0.12268484 | AM25: 3.2454874 | AN25: 131.83637 | AO25: 4.0127416 | AP25: 0.51293276 | AQ25: 0.48938797 | AR25: 0.088787079 | AS25: 0.017103831 | AT25: 2.2051589 | AU25: 4.6079797 | AV25: 26.143183 | AW25: 3.75595 | AX25: 89.648237 | AY25: 415.47871
A26: 2003 | B26: 1.4360411 | C26: 1.3434836 | D26: 0.93621957 | E26: 7.5059999 | F26: 0.57105911 | G26: 0.46381929 | H26: 0.22685474 | I26: 7.9397167 | J26: 0.23743906 | K26: 8.48847 | L26: 11.904888 | M26: 1.9199537 | N26: 6.2685697 | O26: 0.17191024 | P26: 10.602225 | Q26: 0.68072716 | R26: 0.72546447 | S26: 0.32366112 | T26: 2.8271753 | U26: 0.50706653 | V26: 0.8695613 | W26: 0.79904157 | X26: 0.52254796 | Y26: 0.30920214 | Z26: 22.231501 | AA26: 10.820557 | AB26: 0.15067018 | AC26: 4.1130991 | AD26: 0.85090163 | AE26: 0.33498534 | AF26: 21.354958 | AG26: 0.35623455 | AH26: 5.2914761 | AI26: 3.134738 | AJ26: 8.4142154 | AK26: 5.609558 | AL26: 0.21684978 | AM26: 3.0554251 | AN26: 137.85107 | AO26: 3.7609234 | AP26: 0.3500224 | AQ26: 0.58481689 | AR26: 0.16783063 | AS26: 0.018430694 | AT26: 2.4990858 | AU26: 4.2856275 | AV26: 26.497498 | AW26: 4.6957125 | AX26: 89.23892 | AY26: 423.4662
A27: 2004 | B27: 1.3633075 | C27: 1.396604 | D27: 0.65005859 | E27: 7.5586934 | F27: 0.37280042 | G27: 0.53884891 | H27: 0.12730018 | I27: 7.980533 | J27: 0.24517408 | K27: 9.1271912 | L27: 11.767568 | M27: 1.9415886 | N27: 6.2303707 | O27: 0.24585391 | P27: 11.313241 | Q27: 1.1319828 | R27: 0.72473673 | S27: 0.3117344 | T27: 2.5670262 | U27: 0.33713075 | V27: 0.84885582 | W27: 0.77998415 | X27: 0.5080345 | Y27: 0.32169489 | Z27: 21.258023 | AA27: 11.983333 | AB27: 0.13560709 | AC27: 4.1638461 | AD27: 0.5520755 | AE27: 0.39059313 | AF27: 23.377555 | AG27: 0.46206818 | AH27: 5.2897494 | AI27: 2.8203082 | AJ27: 8.6367858 | AK27: 6.1240995 | AL27: 0.18915418 | AM27: 2.7310228 | AN27: 134.61143 | AO27: 4.5124711 | AP27: 0.48506882 | AQ27: 0.49242825 | AR27: 0.15631049 | AS27: 0.02101713 | AT27: 2.8548331 | AU27: 4.2593103 | AV27: 26.242489 | AW27: 4.7031067 | AX27: 90.485076 | AY27: 425.32808
A28: 2005 | B28: 1.3951786 | C28: 1.3658 | D28: 0.68405656 | E28: 7.5983205 | F28: 0.59819462 | G28: 0.49462403 | H28: 0.15772012 | I28: 8.052033 | J28: 0.28764682 | K28: 8.9703435 | L28: 11.76641 | M28: 2.1155911 | N28: 5.9227596 | O28: 0.28852449 | P28: 10.035095 | Q28: 1.3603154 | R28: 0.84986249 | S28: 0.252825 | T28: 2.4365966 | U28: 0.29348198 | V28: 0.7410587 | W28: 0.68092964 | X28: 0.44328675 | Y28: 0.28409605 | Z28: 20.91306 | AA28: 9.665888 | AB28: 0.13335882 | AC28: 4.1687921 | AD28: 0.66062915 | AE28: 0.44304867 | AF28: 22.034631 | AG28: 0.45174283 | AH28: 6.0100998 | AI28: 2.6831304 | AJ28: 9.2056335 | AK28: 6.0518108 | AL28: 0.20587615 | AM28: 2.5154364 | AN28: 125.37006 | AO28: 4.7908426 | AP28: 0.50152866 | AQ28: 0.65861427 | AR28: 0.25305399 | AS28: 0.0092801211 | AT28: 3.0500634 | AU28: 4.4169199 | AV28: 26.68069 | AW28: 4.5403531 | AX28: 93.85837 | AY28: 416.34766
A29: 2006 | B29: 1.6776827 | C29: 1.4102261 | D29: 0.82673705 | E29: 7.9233256 | F29: 0.42718991 | G29: 0.54151384 | H29: 0.1651047 | I29: 8.0141549 | J29: 0.28227196 | K29: 8.9595334 | L29: 11.142395 | M29: 2.0550378 | N29: 6.0832415 | O29: 0.44430978 | P29: 9.1303872 | Q29: 1.0318847 | R29: 0.85108399 | S29: 0.31254395 | T29: 2.6943022 | U29: 0.20668089 | V29: 0.64688876 | W29: 0.75200937 | X29: 0.58055133 | Y29: 0.36593514 | Z29: 20.053726 | AA29: 11.980201 | AB29: 0.10402388 | AC29: 3.9486519 | AD29: 0.94327442 | AE29: 0.4071388 | AF29: 21.682215 | AG29: 0.3247537 | AH29: 5.9064807 | AI29: 2.7531573 | AJ29: 9.4574366 | AK29: 6.3575342 | AL29: 0.19469841 | AM29: 2.9105297 | AN29: 123.65144 | AO29: 4.6777262 | AP29: 0.52358321 | AQ29: 0.40412792 | AR29: 0.19231314 | AS29: 0.015479247 | AT29: 2.4848843 | AU29: 4.5765957 | AV29: 26.114594 | AW29: 4.654487 | AX29: 84.279698 | AY29: 405.12374
A30: 2007 | B30: 1.5485782 | C30: 1.395533 | D30: 0.77098018 | E30: 7.8106939 | F30: 0.33186656 | G30: 0.55369926 | H30: 0.1646911 | I30: 8.312236 | J30: 0.30096193 | K30: 8.9569336 | L30: 10.477436 | M30: 2.0448789 | N30: 6.2879438 | O30: 0.44634805 | P30: 10.156349 | Q30: 1.3943325 | R30: 0.85513085 | S30: 0.26642274 | T30: 2.7199912 | U30: 0.26917835 | V30: 1.0299874 | W30: 0.60619424 | X30: 0.50254829 | Y30: 0.39337138 | Z30: 18.37564 | AA30: 11.542505 | AB30: 0.097865138 | AC30: 4.0498222 | AD30: 0.98366954 | AE30: 0.45139366 | AF30: 22.635361 | AG30: 0.28344003 | AH30: 5.7896311 | AI30: 3.0304288 | AJ30: 9.3643227 | AK30: 5.8565452 | AL30: 0.18013464 | AM30: 2.7084082 | AN30: 124.34935 | AO30: 4.9667032 | AP30: 0.51905351 | AQ30: 0.48577432 | AR30: 0.18196555 | AS30: 0.010988567 | AT30: 2.4236556 | AU30: 4.1253599 | AV30: 26.053411 | AW30: 5.0900309 | AX30: 87.902579 | AY30: 409.05433
A31: 2008 | B31: 1.536883 | C31: 1.4815874 | D31: 0.73628547 | E31: 7.3870541 | F31: 0.47164661 | G31: 0.53488515 | H31: 0.18419999 | I31: 8.7307869 | J31: 0.32334531 | K31: 8.9881327 | L31: 10.563825 | M31: 2.014759 | N31: 6.2226889 | O31: 0.33863146 | P31: 9.9317921 | Q31: 0 | R31: 0.77653373 | S31: 0.21427061 | T31: 2.7649058 | U31: 0.20119297 | V31: 1.0516746 | W31: 0.46967322 | X31: 0.41633482 | Y31: 0.38189369 | Z31: 16.849552 | AA31: 10.406753 | AB31: 0.12415441 | AC31: 3.9074103 | AD31: 0.99394868 | AE31: 0.44916993 | AF31: 21.693139 | AG31: 0.23 | AH31: 5.7578437 | AI31: 2.9324092 | AJ31: 9.4721644 | AK31: 6.1913232 | AL31: 0.17740356 | AM31: 2.7571174 | AN31: 118.28555 | AO31: 4.6774003 | AP31: 0.51007165 | AQ31: 0.65280605 | AR31: 0.24853499 | AS31: 0.0069968076 | AT31: 2.558338 | AU31: 4.1458613 | AV31: 24.998267 | AW31: 5.0688895 | AX31: 85.623984 | AY31: 394.44207
... A46: 2023 | B46: 1.1521747 | C46: 1.5832905 | D46: 0.27528021 | E46: 4.983105 | F46: 0.52619792 | G46: 1.4324435 | H46: 0.099356776 | I46: 8.4168675 | J46: 1.281661 | K46: 6.3536729 | L46: 10.13618 | M46: 2.584998 | N46: 4.6490801 | O46: 1.4438038 | P46: 11.650783 | Q46: 3.8204095 | R46: 0.98595361 | S46: 0.21197667 | T46: 2.0249773 | U46: 0.20165257 | V46: 1.2486295 | W46: 0.57472705 | X46: 0.34524723 | Y46: 0.84239024 | Z46: 13.154749 | AA46: 17.880828 | AB46: 0.092863227 | AC46: 3.5430186 | AD46: 0.61398486 | AE46: 0.6377096 | AF46: 22.689234 | AG46: 1.32482e-05 | AH46: 12.606657 | AI46: 1.8172362 | AJ46: 10.85162 | AK46: 7.6486386 | AL46: 0.1253232 | AM46: 2.2041053 | AN46: 116.15247 | AO46: 5.7916389 | AP46: 0.99655881 | AQ46: 0.20929919 | AR46: 0.25844135 | AS46: 0.036711789 | AT46: 2.9499173 | AU46: 5.2267052 | AV46: 18.058636 | AW46: 5.2706073 | AX46: 71.850119 | AY46: 387.49194
A47: 2024 | B47: 1.1374669 | C47: 1.4951891 | D47: 0.25565821 | E47: 4.3221444 | F47: 0.51892503 | G47: 1.8799281 | H47: 0.092998523 | I47: 7.9825164 | J47: 1.4051895 | K47: 6.455015 | L47: 8.8229203 | M47: 2.5560014 | N47: 4.717101 | O47: 1.3169734 | P47: 10.761023 | Q47: 3.1339494 | R47: 1.0301793 | S47: 0.21181832 | T47: 1.9676982 | U47: 0.25272611 | V47: 1.2463787 | W47: 0.55879238 | X47: 0.36868744 | Y47: 0.35665802 | Z47: 12.398241 | AA47: 16.169088 | AB47: NA | AC47: 3.3136457 | AD47: 0.41365095 | AE47: 0.70582218 | AF47: 22.937444 | AG47: 0.11184839 | AH47: 12.906797 | AI47: 1.6724451 | AJ47: 10.825994 | AK47: 7.835532 | AL47: 0.13386565 | AM47: 3.1559024 | AN47: 116.29635 | AO47: 5.1343853 | AP47: 0.96517433 | AQ47: 0.27525762 | AR47: 0.3013793 | AS47: NA | AT47: 2.1291619 | AU47: 5.140522 | AV47: 14.972304 | AW47: 5.5184446 | AX47: 67.363681 | AY47: 373.52288
A48: NA = Not available. Most recent year is preliminary. Totals may not sum due to rounding.
A49: 1/ Unit of measure is pounds per person.
A50: 2/ Other processing includes all other canned and frozen vegetables for processing except potatoes, sweet potatoes, and dry pulse crops. Beginning with 2017, also includes miscellaneous vegetables for dehydrating.
A51: Source: USDA, Economic Research Service.

Sheet Table 2a-PerCapitaAvail, Fresh
A1: Table 2a--Vegetables, fresh market (including mushrooms and sweet potatoes): Selected U.S. per capita availability/1,2 | O1: =HYPERLINK("#'"&"Index'!A1","INDEX") -> INDEX
A2: Year | B2: Artichoke/3 | C2: Asparagus | D2: Beans, snap green | E2: Broccoli | F2: Cabbage | G2: Carrot | H2: Cauliflower | I2: Celery/3 | J2: Cucumber | K2: Eggplant/3 | L2: Escarole /Endive | M2: Garlic/3 | N2: Greens, southern and other leafy/4 | O2: Lettuce, head | P2: Lettuce, leaf/ romaine | Q2: Mushrooms | R2: Onions | S2: Peppers, bell/3 | T2: Pumpkin | U2: Radish | V2: Spinach | W2: Squash | X2: Sweet corn | Y2: Sweet potatoes, all uses | Z2: Tomato/5 | AA2: Other fresh vegetables, all/6 | AB2: Fresh vegetables, total
A3: 1980 | B3: 0.587 | C3: 0.294 | D3: 1.315 | E3: 1.401 | F3: 7.997 | G3: 6.151 | H3: 1.134 | I3: 7.372 | J3: 3.862 | K3: 0.477 | L3: 0.451 | M3: 0.861 | N3: NA | O3: 25.745 | P3: NA | Q3: 1.137 | R3: 11.383 | S3: 2.885 | T3: NA | U3: 0.565 | V3: 0.444 | W3: 2.308 | X3: 6.498 | Y3: 4.387 | Z3: 12.88 | AA3: 0.596 | AB3: 100.73
A4: 1981 | B4: 0.748 | C4: 0.31 | D4: 1.257 | E4: 1.657 | F4: 8.152 | G4: 6.119 | H4: 1.368 | I4: 7.272 | J4: 4 | K4: 0.458 | L4: 0.443 | M4: 0.659 | N4: NA | O4: 25.028 | P4: NA | Q4: 1.203 | R4: 10.734 | S4: 2.786 | T4: NA | U4: 0.575 | V4: 0.527 | W4: 2.325 | X4: 6.233 | Y4: 4.672 | Z4: 12.451 | AA4: 0.707 | AB4: 99.684
A5: 1982 | B5: 0.823 | C5: 0.377 | D5: 1.26 | E5: 1.987 | F5: 8.557 | G5: 6.603 | H5: 1.327 | I5: 7.412 | J5: 4.186 | K5: 0.514 | L5: 0.377 | M5: 0.757 | N5: NA | O5: 25.024 | P5: NA | Q5: 1.386 | R5: 12.244 | S5: 2.972 | T5: NA | U5: 0.501 | V5: 0.55 | W5: 2.457 | X5: 6.018 | Y5: 5.393 | Z5: 13.006 | AA5: 0.635 | AB5: 104.366
A6: 1983 | B6: 0.735 | C6: 0.432 | D6: 1.239 | E6: 2.031 | F6: 8.206 | G6: 6.49 | H6: 1.415 | I6: 7.001 | J6: 4.537 | K6: 0.513 | L6: 0.395 | M6: 0.997 | N6: NA | O6: 22.525 | P6: NA | Q6: 1.449 | R6: 12.165 | S6: 3.326 | T6: NA | U6: 0.547 | V6: 0.513 | W6: 2.556 | X6: 6.145 | Y6: 4.485 | Z6: 13.565 | AA6: 0.746 | AB6: 102.013
A7: 1984 | B7: 0.955 | C7: 0.406 | D7: 1.343 | E7: 2.458 | F7: 8.568 | G7: 6.684 | H7: 1.824 | I7: 7.115 | J7: 4.653 | K7: 0.469 | L7: 0.387 | M7: 0.769 | N7: NA | O7: 24.989 | P7: NA | Q7: 1.654 | R7: 13.077 | S7: 3.625 | T7: NA | U7: 0.495 | V7: 0.53 | W7: 2.625 | X7: 6.436 | Y7: 4.832 | Z7: 14.29 | AA7: 0.752 | AB7: 108.936
A8: 1985 | B8: 1.023 | C8: 0.465 | D8: 1.26 | E8: 2.579 | F8: 8.737 | G8: 6.491 | H8: 1.839 | I8: 6.88 | J8: 4.394 | K8: 0.458 | L8: 0.389 | M8: 1.062 | N8: NA | O8: 23.751 | P8: 3.265 | Q8: 1.773 | R8: 13.624 | S8: 3.8 | T8: NA | U8: 0.512 | V8: 0.674 | W8: 2.672 | X8: 6.413 | Y8: 5.26 | Z8: 14.901 | AA8: 0.711 | AB8: 112.933
A9: 1986 | B9: 0.935 | C9: 0.603 | D9: 1.256 | E9: 3.047 | F9: 8.641 | G9: 6.484 | H9: 2.185 | I9: 6.493 | J9: 4.625 | K9: 0.467 | L9: 0.366 | M9: 0.766 | N9: NA | O9: 22.008 | P9: 2.374 | Q9: 1.785 | R9: 13.736 | S9: 3.965 | T9: NA | U9: 0.464 | V9: 0.585 | W9: 2.775 | X9: 6.061 | Y9: 4.262 | Z9: 15.912 | AA9: 0.612 | AB9: 110.407
A10: 1987 | B10: 0.993 | C10: 0.566 | D10: 1.217 | E10: 3.088 | F10: 9.078 | G10: 8.296 | H10: 2.132 | I10: 6.594 | J10: 5.067 | K10: 0.473 | L10: 0.341 | M10: 1.188 | N10: NA | O10: 25.797 | P10: 2.525 | Q10: 1.892 | R10: 13.411 | S10: 4.229 | T10: 3.014 | U10: 0.513 | V10: 0.583 | W10: 2.879 | X10: 6.262 | Y10: 4.302 | Z10: 15.963 | AA10: 0.472 | AB10: 120.875
A11: 1988 | B11: 0.915 | C11: 0.582 | D11: 1.19 | E11: 3.774 | F11: 9.007 | G11: 7.094 | H11: 2.194 | I11: 7.153 | J11: 4.824 | K11: 0.39 | L11: 0.358 | M11: 1.086 | N11: NA | O11: 27.167 | P11: 3.201 | Q11: 1.935 | R11: 14.549 | S11: 4.476 | T11: 3.806 | U11: 0.55 | V11: 0.596 | W11: 3.077 | X11: 5.819 | Y11: 3.931 | Z11: 16.943 | AA11: 0.671 | AB11: 125.288
A12: 1989 | B12: 0.974 | C12: 0.57 | D12: 1.194 | E12: 3.804 | F12: 8.603 | G12: 8.086 | H12: 2.311 | I12: 7.474 | J12: 4.784 | K12: 0.399 | L12: 0.33 | M12: 1.015 | N12: NA | O12: 28.685 | P12: 3.563 | Q12: 1.992 | R12: 14.763 | S12: 4.689 | T12: 4.82 | U12: 0.708 | V12: 0.642 | W12: 3.452 | X12: 6.528 | Y12: 3.925 | Z12: 16.843 | AA12: 0.775 | AB12: 130.929
A13: 1990 | B13: 0.846 | C13: 0.587 | D13: 1.069 | E13: 3.368 | F13: 8.337 | G13: 8.291 | H13: 2.191 | I13: 7.194 | J13: 4.674 | K13: 0.399 | L13: 0.262 | M13: 1.407 | N13: NA | O13: 27.747 | P13: 3.77 | Q13: 2.054 | R13: 15.06 | S13: 5.881 | T13: 4.433 | U13: 0.659 | V13: 0.756 | W13: 3.506 | X13: 6.742 | Y13: 4.399 | Z13: 15.523 | AA13: 0.561 | AB13: 129.716
A14: 1991 | B14: 0.827 | C14: 0.601 | D14: 1.123 | E14: 3.043 | F14: 8.204 | G14: 7.713 | H14: 1.952 | I14: 6.733 | J14: 4.558 | K14: 0.411 | L14: 0.247 | M14: 1.487 | N14: NA | O14: 26.045 | P14: 3.997 | Q14: 2.005 | R14: 15.687 | S14: 6.301 | T14: 4.429 | U14: 0.548 | V14: 0.804 | W14: 3.672 | X14: 5.908 | Y14: 3.867 | Z14: 15.361 | AA14: 0.545 | AB14: 126.068
A15: 1992 | B15: 0.879 | C15: 0.596 | D15: 1.447 | E15: 3.416 | F15: 8.663 | G15: 8.29 | H15: 1.807 | I15: 7.323 | J15: 4.928 | K15: 0.47 | L15: 0.32 | M15: 1.461 | N15: NA | O15: 25.791 | P15: 4.67 | Q15: 1.938 | R15: 16.101 | S15: 7.102 | T15: 4.058 | U15: 0.476 | V15: 0.817 | W15: 3.806 | X15: 6.869 | Y15: 4.076 | Z15: 15.446 | AA15: 0.613 | AB15: 131.363
A16: 1993 | B16: 0.864 | C16: 0.567 | D16: 1.515 | E16: 3.333 | F16: 9.323 | G16: 10.847 | H16: 2.091 | I16: 7.261 | J16: 5.212 | K16: 0.471 | L16: 0.3 | M16: 1.746 | N16: NA | O16: 24.4 | P16: 5.042 | Q16: 1.998 | R16: 17.174 | S16: 7.631 | T16: 5.126 | U16: 0.517 | V16: 0.665 | W16: 3.785 | X16: 6.977 | Y16: 3.66 | Z16: 16.303 | AA16: 0.769 | AB16: 137.577
A17: 1994 | B17: 1.266 | C17: 0.559 | D17: 1.539 | E17: 4.43 | F17: 9.082 | G17: 12.677 | H17: 2.021 | I17: 7.237 | J17: 5.363 | K17: 0.516 | L17: 0.329 | M17: 1.797 | N17: NA | O17: 25.007 | P17: 5.678 | Q17: 1.986 | R17: 16.918 | S17: 7.059 | T17: 5.491 | U17: 0.436 | V17: 0.752 | W17: 3.93 | X17: 8.155 | Y17: 4.463 | Z17: 16.212 | AA17: 0.624 | AB17: 143.527
A18: 1995 | B18: 0.925 | C18: 0.557 | D18: 1.636 | E18: 4.307 | F18: 8.123 | G18: 11.191 | H18: 1.637 | I18: 6.934 | J18: 5.609 | K18: 0.473 | L18: 0.304 | M18: 1.85 | N18: NA | O18: 22.167 | P18: 5.895 | Q18: 2.033 | R18: 17.781 | S18: 7.011 | T18: 5.896 | U18: 0.414 | V18: 0.671 | W18: 3.746 | X18: 7.823 | Y18: 4.208 | Z18: 16.842 | AA18: 0.78 | AB18: 138.813
A19: 1996 | B19: 0.989 | C19: 0.578 | D19: 1.452 | E19: 4.516 | F19: 8.258 | G19: 12.37 | H19: 1.721 | I19: 7.027 | J19: 5.93 | K19: 0.599 | L19: 0.319 | M19: 2.295 | N19: NA | O19: 21.575 | P19: 5.818 | Q19: 2.036 | R19: 18.323 | S19: 8.069 | T19: 5.775 | U19: 0.407 | V19: 0.628 | W19: 3.69 | X19: 8.326 | Y19: 4.287 | Z19: 17.403 | AA19: 0.704 | AB19: 143.095
A20: 1997 | B20: 1.01 | C20: 0.659 | D20: 1.35 | E20: 4.965 | F20: 9.013 | G20: 14.114 | H20: 1.765 | I20: 6.549 | J20: 6.423 | K20: 0.65 | L20: 0.299 | M20: 1.995 | N20: 2.429 | O20: 23.902 | P20: 6.595 | Q20: 2.092 | R20: 18.839 | S20: 7.334 | T20: 5.648 | U20: 0.506 | V20: 1.107 | W20: 3.85 | X20: 8.29 | Y20: 4.261 | Z20: 17.295 | AA20: 0.507 | AB20: 151.447
A21: 1998 | B21: 1.18 | C21: 0.731 | D21: 1.641 | E21: 5.045 | F21: 8.428 | G21: 9.527 | H21: 1.459 | I21: 6.467 | J21: 6.49 | K21: 0.7 | L21: 0.304 | M21: 2.584 | N21: 2.391 | O21: 22.325 | P21: 6.615 | Q21: 2.328 | R21: 18.4 | S21: 7.763 | T21: 6.357 | U21: 0.445 | V21: 0.97 | W21: 4.16 | X21: 9.334 | Y21: 3.848 | Z21: 18.497 | AA21: 0.583 | AB21: 148.572
A22: 1999 | B22: 1.321 | C22: 0.894 | D22: 1.895 | E22: 6.159 | F22: 7.554 | G22: 9.253 | H22: 1.764 | I22: 6.532 | J22: 6.729 | K22: 0.666 | L22: 0.225 | M22: 3.292 | N22: 2.367 | O22: 24.909 | P22: 7.592 | Q22: 2.464 | R22: 18.478 | S22: 7.719 | T22: 5.921 | U22: 0.392 | V22: 0.972 | W22: 4.098 | X22: 9.095 | Y22: 3.718 | Z22: 19.068 | AA22: 0.554 | AB22: 153.631
A23: 2000 | B23: 1.242 | C23: 0.957 | D23: 2.016 | E23: 5.888 | F23: 8.9 | G23: 9.204 | H23: 1.737 | I23: 6.269 | J23: 6.351 | K23: 0.807 | L23: 0.345 | M23: 2.22 | N23: 2.408 | O23: 23.461 | P23: 8.385 | Q23: 2.492 | R23: 18.874 | S23: 8.186 | T23: 4.599 | U23: 0.481 | V23: 1.375 | W23: 4.431 | X23: 9.04 | Y23: 4.205 | Z23: 18.985 | AA23: 0.547 | AB23: 153.405
A24: 2001 | B24: 1.23 | C24: 0.92 | D24: 2.165 | E24: 5.399 | F24: 8.828 | G24: 9.38 | H24: 1.519 | I24: 6.412 | J24: 6.268 | K24: 0.832 | L24: 0.35 | M24: 2.416 | N24: 2.33 | O24: 22.988 | P24: 8.027 | Q24: 2.591 | R24: 18.468 | S24: 8.119 | T24: 4.102 | U24: 0.508 | V24: 1.073 | W24: 4.197 | X24: 9.173 | Y24: 4.369 | Z24: 19.203 | AA24: 0.558 | AB24: 151.425
A25: 2002 | B25: 1.324 | C25: 0.964 | D25: 2.093 | E25: 5.351 | F25: 8.295 | G25: 8.417 | H25: 1.425 | I25: 6.302 | J25: 6.623 | K25: 0.719 | L25: 0.31 | M25: 2.5 | N25: 2.263 | O25: 22.543 | P25: 9.594 | Q25: 2.582 | R25: 19.323 | S25: 8.265 | T25: 4.013 | U25: 0.513 | V25: 1.431 | W25: 4.608 | X25: 8.974 | Y25: 3.756 | Z25: 20.311 | AA25: 0.494 | AB25: 152.993
A26: 2003 | B26: 1.436 | C26: 1.043 | D26: 1.967 | E26: 5.347 | F26: 7.397 | G26: 8.779 | H26: 1.559 | I26: 6.269 | J26: 6.158 | K26: 0.725 | L26: 0.324 | M26: 2.827 | N26: 2.5 | O26: 22.232 | P26: 10.821 | Q26: 2.62 | R26: 19.507 | S26: 8.414 | T26: 3.761 | U26: 0.35 | V26: 1.607 | W26: 4.286 | X26: 9.166 | Y26: 4.696 | Z26: 19.412 | AA26: 0.633 | AB26: 153.836
A27: 2004 | B27: 1.363 | C27: 1.125 | D27: 1.882 | E27: 5.314 | F27: 8.043 | G27: 8.721 | H27: 1.559 | I27: 6.23 | J27: 6.43 | K27: 0.725 | L27: 0.312 | M27: 2.567 | N27: 2.459 | O27: 21.258 | P27: 11.983 | Q27: 2.644 | R27: 21.917 | S27: 8.637 | T27: 4.512 | U27: 0.485 | V27: 1.845 | W27: 4.259 | X27: 8.962 | Y27: 4.703 | Z27: 19.95 | AA27: 0.702 | AB27: 158.587
A28: 2005 | B28: 1.395 | C28: 1.116 | D28: 1.801 | E28: 5.342 | F28: 7.757 | G28: 8.665 | H28: 1.751 | I28: 5.923 | J28: 6.193 | K28: 0.85 | L28: 0.253 | M28: 2.437 | N28: 2.149 | O28: 20.913 | P28: 9.666 | Q28: 2.608 | R28: 20.897 | S28: 9.206 | T28: 4.791 | U28: 0.502 | V28: 2.329 | W28: 4.417 | X28: 8.652 | Y28: 4.54 | Z28: 20.151 | AA28: 0.764 | AB28: 155.068
A29: 2006 | B29: 1.678 | C29: 1.134 | D29: 2.08 | E29: 5.761 | F29: 7.751 | G29: 8.108 | H29: 1.697 | I29: 6.083 | J29: 6.14 | K29: 0.851 | L29: 0.313 | M29: 2.694 | N29: 2.345 | O29: 20.054 | P29: 11.98 | Q29: 2.638 | R29: 19.916 | S29: 9.457 | T29: 4.678 | U29: 0.524 | V29: 1.962 | W29: 4.577 | X29: 8.326 | Y29: 4.654 | Z29: 19.77 | AA29: 0.725 | AB29: 155.896
A30: 2007 | B30: 1.549 | C30: 1.161 | D30: 2.198 | E30: 5.636 | F30: 7.951 | G30: 8.05 | H30: 1.68 | I30: 6.288 | J30: 6.423 | K30: 0.855 | L30: 0.266 | M30: 2.72 | N30: 2.532 | O30: 18.376 | P30: 11.543 | Q30: 2.569 | R30: 21.612 | S30: 9.364 | T30: 4.967 | U30: 0.519 | V30: 1.614 | W30: 4.125 | X30: 9.225 | Y30: 5.09 | Z30: 19.208 | AA30: 0.78 | AB30: 156.301
A31: 2008 | B31: 1.537 | C31: 1.185 | D31: 1.987 | E31: 6.035 | F31: 8.051 | G31: 8.067 | H31: 1.572 | I31: 6.223 | J31: 6.388 | K31: 0.777 | L31: 0.214 | M31: 2.765 | N31: 2.32 | O31: 16.85 | P31: 10.407 | Q31: 2.47 | R31: 20.185 | S31: 9.472 | T31: 4.677 | U31: 0.51 | V31: 1.708 | W31: 4.146 | X31: 9.012 | Y31: 5.069 | Z31: 18.514 | AA31: 0.793 | AB31: 150.934
... A47: 2024 | B47: 1.137 | C47: 1.433 | D47: 1.315 | E47: 5.596 | F47: 5.539 | G47: 7.066 | H47: 2.074 | I47: 4.717 | J47: 8.318 | K47: 1.03 | L47: 0.212 | M47: 1.968 | N47: 2.531 | O47: 12.398 | P47: 16.169 | Q47: 2.275 | R47: 21.257 | S47: 10.826 | T47: 5.134 | U47: 0.965 | V47: 1.541 | W47: 5.141 | X47: 4.565 | Y47: 5.518 | Z47: 19.102 | AA47: 2.117 | AB47: 149.944
A48: NA = Not available. Most recent year is preliminary. Totals may not sum due to rounding.
A49: 1/ Unit of measure is pounds per person.
A50: 2/ Excludes potatoes.
A51: 3/ Includes fresh and dual use, which includes both fresh and processing.
A52: 4/ Collards, kale, mustard greens, and turnip greens.
A53: 5/ After 1996, includes an USDA, ERS estimate of domestically produced hothouse tomatoes. Hothouse tomato imports are included in all years.
A54: 6/ Other includes brussels sprouts, okra, and fresh green limas.
A55: Source: USDA, Economic Research Service.

Sheet Table 2b-PerCapitaAvail, Pr
A1: Table 2b--Vegetables, processing: Selected U.S. per capita availability/1 | O1: =HYPERLINK("#'"&"Index'!A1","INDEX") -> INDEX
A2: Year | B2: Asparagus, processing | C2: Beans, green lima, processing | D2: Beans, snap green, processing | E2: Beets, processing | F2: Broccoli, processing | G2: Cabbage, processing | H2: Carrots, processing | I2: Cauliflower, processing | J2: Corn, sweet, processing | K2: Cucumbers, processing | L2: Mushrooms, processing | M2: Onions, dehydrating/2 | N2: Peas, green, processing | O2: Peppers, chili/3 | P2: Spinach, processing | Q2: Tomatoes, processing | R2: Other, processing/4 | S2: Processing, total/5
A3: 1980 | B3: 0.492 | C3: 0.65 | D3: 5.917 | E3: 1.82 | F3: 1.455 | G3: 1.986 | H3: 3.474 | I3: 0.782 | J3: 19.433 | K3: 5.397 | L3: 1.744 | M3: 0.771 | N3: 4.467 | O3: 3.049 | P3: 1.363 | Q3: 64.102 | R3: 1.461 | S3: 118.363
A4: 1981 | B4: 0.485 | C4: 0.69 | D4: 6.306 | E4: 1.614 | F4: 1.564 | G4: 2.027 | H4: 3.445 | I4: 0.91 | J4: 18.416 | K4: 5.344 | L4: 1.536 | M4: 0.821 | N4: 4.434 | O4: 3.268 | P4: 1.266 | Q4: 59.804 | R4: 1.566 | S4: 113.496
A5: 1982 | B5: 0.343 | C5: 0.571 | D5: 5.73 | E5: 1.345 | F5: 1.517 | G5: 1.697 | H5: 2.941 | I5: 0.895 | J5: 17.348 | K5: 5.107 | L5: 1.542 | M5: 2.004 | N5: 4.138 | O5: 3.055 | P5: 1.126 | Q5: 60.406 | R5: 1.554 | S5: 111.319
A6: 1983 | B6: 0.406 | C6: 0.465 | D6: 5.54 | E6: 1.258 | F6: 1.568 | G6: 2.078 | H6: 3.049 | I6: 0.848 | J6: 18.273 | K6: 5.156 | L6: 1.519 | M6: 1.657 | N6: 4.211 | O6: 3.309 | P6: 1.087 | Q6: 61.173 | R6: 1.634 | S6: 113.231
A7: 1984 | B7: 0.406 | C7: 0.682 | D7: 5.491 | E7: 1.244 | F7: 1.743 | G7: 1.698 | H7: 3.98 | I7: 0.95 | J7: 18.202 | K7: 5.227 | L7: 1.814 | M7: 1.484 | N7: 4.027 | O7: 3.614 | P7: 0.833 | Q7: 68.74 | R7: 1.373 | S7: 121.508
A8: 1985 | B8: 0.397 | C8: 0.572 | D8: 5.63 | E8: 0.874 | F8: 1.961 | G8: 1.592 | H8: 3.17 | I8: 0.928 | J8: 19.794 | K8: 5.826 | L8: 1.769 | M8: 1.573 | N8: 4.143 | O8: 3.911 | P8: 1.049 | Q8: 63.386 | R8: 1.391 | S8: 117.966
A9: 1986 | B9: 0.387 | C9: 0.595 | D9: 5.378 | E9: 1.061 | F9: 1.785 | G9: 1.551 | H9: 2.982 | I9: 0.926 | J9: 19.646 | K9: 5.326 | L9: 1.818 | M9: 1.891 | N9: 4.08 | O9: 4.175 | P9: 0.899 | Q9: 63.931 | R9: 1.626 | S9: 118.057
A10: 1987 | B10: 0.381 | C10: 0.539 | D10: 5.434 | E10: 0.762 | F10: 2.216 | G10: 1.611 | H10: 3.141 | I10: 0.945 | J10: 18.47 | K10: 5.535 | L10: 1.889 | M10: 1.519 | N10: 3.731 | O10: 4.165 | P10: 0.774 | Q10: 65.49 | R10: 1.587 | S10: 118.189
A11: 1988 | B11: 0.455 | C11: 0.432 | D11: 5.503 | E11: 0.888 | F11: 2.416 | G11: 1.434 | H11: 3.359 | I11: 0.944 | J11: 19.1 | K11: 5.279 | L11: 1.651 | M11: 1.668 | N11: 3.657 | O11: 4.315 | P11: 0.928 | Q11: 61.675 | R11: 2.014 | S11: 115.718
A12: 1989 | B12: 0.38 | C12: 0.393 | D12: 5.881 | E12: 0.815 | F12: 2.169 | G12: 1.283 | H12: 3.384 | I12: 0.751 | J12: 17.907 | K12: 5.19 | L12: 1.551 | M12: 1.614 | N12: 3.71 | O12: 4.504 | P12: 0.771 | Q12: 69.397 | R12: 1.848 | S12: 121.548
A13: 1990 | B13: 0.419 | C13: 0.34 | D13: 5.632 | E13: 0.855 | F13: 2.233 | G13: 1.194 | H13: 4.085 | I13: 0.758 | J13: 19.548 | K13: 4.994 | L13: 1.537 | M13: 2.134 | N13: 4.162 | O13: 4.831 | P13: 0.565 | Q13: 75.313 | R13: 2.532 | S13: 131.132
A14: 1991 | B14: 0.368 | C14: 0.409 | D14: 5.866 | E14: 0.76 | F14: 2.252 | G14: 1.435 | H14: 3.567 | I14: 0.582 | J14: 20.425 | K14: 5.056 | L14: 1.71 | M14: 1.572 | N14: 4.154 | O14: 4.513 | P14: 0.994 | Q14: 77.109 | R14: 2.89 | S14: 133.662
... A47: 2024 | B47: 0.062 | C47: 0.249 | D47: 3.007 | E47: 0.519 | F47: 2.386 | G47: 0.916 | H47: 1.757 | I47: 0.482 | J47: 10.407 | K47: 2.443 | L47: 1.039 | M47: 1.68 | N47: 1.672 | O47: 7.836 | P47: 0.588 | Q47: 48.261 | R47: 12.907 | S47: 96.211
A48: Most recent year is preliminary. Totals may not sum due to rounding.
A49: 1/ Unit of measure is pounds per person.
A50: 2/ Excludes onions used for canning and freezing.
A51: 3/ Includes use expressed on a fresh-weight equivalent basis.
A52: 4/ Includes all other canned and frozen vegetables for processing except potatoes, sweet potatoes, and dry pulse crops. Beginning with 2017, also includes miscellaneous vegetables for dehydrating.
A53: 5/ Excludes potatoes, sweet potatoes, and dry pulse crops.
A54: Source: USDA, Economic Research Service.

Sheet Table 2c-PerCapitaAvail, Potato
A1: Table 2c--Potatoes: U.S. per capita availability/1 | O1: =HYPERLINK("#'"&"Index'!A1","INDEX") -> INDEX
A2: Year | B2: Fresh potatoes | C2: Canning potatoes | D2: Chipping potatoes | E2: Dehydrating potatoes | F2: Freezing potatoes | G2: Processing potatoes, total | H2: All potatoes
A3: 1970 | B3: 61.8 | C3: 1.964 | D3: 17.4 | E3: 12 | F3: 28.5 | G3: 59.864 | H3: 121.664
A4: 1971 | B4: 56.1 | C4: 2.121 | D4: 17.2 | E4: 12.3 | F4: 30.1 | G4: 61.721 | H4: 117.821
A5: 1972 | B5: 57.9 | C5: 2.113 | D5: 16.7 | E5: 12.4 | F5: 30.3 | G5: 61.513 | H5: 119.413
A6: 1973 | B6: 52.4 | C6: 2.244 | D6: 16.3 | E6: 13.1 | F6: 34.2 | G6: 65.844 | H6: 118.244
A7: 1974 | B7: 49.4 | C7: 2.296 | D7: 15.7 | E7: 14.5 | F7: 35.3 | G7: 67.796 | H7: 117.196
A8: 1975 | B8: 52.6 | C8: 1.999 | D8: 15.5 | E8: 14.7 | F8: 37.1 | G8: 69.299 | H8: 121.899
A9: 1976 | B9: 49.4 | C9: 1.947 | D9: 15.8 | E9: 16.3 | F9: 41.8 | G9: 75.847 | H9: 125.247
A10: 1977 | B10: 50.1 | C10: 2.212 | D10: 16.2 | E10: 11.4 | F10: 42.2 | G10: 72.012 | H10: 122.112
A11: 1978 | B11: 46 | C11: 2.26 | D11: 16.5 | E11: 12.1 | F11: 42.6 | G11: 73.46 | H11: 119.46
A12: 1979 | B12: 49.3 | C12: 2.114 | D12: 16.7 | E12: 11.2 | F12: 38.5 | G12: 68.514 | H12: 117.814
A13: 1980 | B13: 51.122 | C13: 1.927 | D13: 16.5 | E13: 9.8 | F13: 35.405 | G13: 63.632 | H13: 114.754
A14: 1981 | B14: 45.845 | C14: 1.786 | D14: 16.6 | E14: 10.8 | F14: 41.486 | G14: 70.672 | H14: 116.517
... A57: 2024 | B57: 28.52 | C57: 0.293 | D57: 17.403 | E57: 11.09 | F57: 58.99 | G57: 87.776 | H57: 116.296
A58: Most recent year is preliminary.
A59: 1/ Unit of measure is pounds per person.
A60: Source: USDA, Economic Research Service.

Sheet Table 2d-PerCapitaAvail, Pulse
A1: Table 2d--Selected dry pulse crops: U.S. per capita availability/1 | O1: =HYPERLINK("#'"&"Index'!A1","INDEX") -> INDEX
A2: Year | B2: Black beans | C2: Blackeye beans | D2: Chickpeas (garbanzo) | E2: Great Northern beans | F2: Lima beans, all | G2: Navy beans | H2: Pink beans | I2: Pinto beans | J2: Red kidney beans, all | K2: Small red beans | L2: Other beans/2 | M2: All dry edible beans | N2: Dry bean total, less garbanzo | O2: Dry peas and lentils | P2: All dry pulses
A3: 1970 | B3: 0.006 | C3: NA | D3: NA | E3: 0.389 | F3: 0.357 | G3: 1.687 | H3: NA | I3: 2.242 | J3: 0.445 | K3: NA | L3: 1.117 | M3: 6.243 | N3: 6.243 | O3: 0.713 | P3: 6.956
A4: 1971 | B4: 0.03 | C4: NA | D4: NA | E4: 0.455 | F4: 0.306 | G4: 1.775 | H4: NA | I4: 2.453 | J4: 0.548 | K4: NA | L4: 1.187 | M4: 6.754 | N4: 6.754 | O4: 0.656 | P4: 7.41
A5: 1972 | B5: 0.025 | C5: NA | D5: NA | E5: 0.367 | F5: 0.258 | G5: 1.844 | H5: NA | I5: 1.955 | J5: 0.29 | K5: NA | L5: 1.026 | M5: 5.765 | N5: 5.765 | O5: 0.791 | P5: 6.556
A6: 1973 | B6: 0.01 | C6: NA | D6: NA | E6: 0.404 | F6: 0.339 | G6: 2.363 | H6: NA | I6: 2.485 | J6: 0.448 | K6: NA | L6: 1.391 | M6: 7.44 | N6: 7.44 | O6: 0.546 | P6: 7.986
A7: 1974 | B7: 0.024 | C7: NA | D7: NA | E7: 0.566 | F7: 0.38 | G7: 1.22 | H7: NA | I7: 1.317 | J7: 0.5 | K7: NA | L7: 1.477 | M7: 5.484 | N7: 5.484 | O7: 0.69 | P7: 6.174
A8: 1975 | B8: 0.026 | C8: NA | D8: NA | E8: 0.588 | F8: 0.411 | G8: 2.302 | H8: NA | I8: 1.682 | J8: 0.509 | K8: NA | L8: 1.269 | M8: 6.787 | N8: 6.787 | O8: 0.376 | P8: 7.163
A9: 1976 | B9: 0.007 | C9: NA | D9: NA | E9: 0.433 | F9: 0.268 | G9: 1.369 | H9: NA | I9: 2.53 | J9: 0.594 | K9: NA | L9: 1.029 | M9: 6.23 | N9: 6.23 | O9: 0.568 | P9: 6.798
A10: 1977 | B10: 0.009 | C10: NA | D10: NA | E10: 0.376 | F10: 0.266 | G10: 2.119 | H10: NA | I10: 2.031 | J10: 0.535 | K10: NA | L10: 1.297 | M10: 6.633 | N10: 6.633 | O10: 0.327 | P10: 6.96
A11: 1978 | B11: 0.028 | C11: NA | D11: NA | E11: 0.326 | F11: 0.294 | G11: 1.164 | H11: NA | I11: 1.852 | J11: 0.521 | K11: NA | L11: 0.879 | M11: 5.064 | N11: 5.064 | O11: 0.614 | P11: 5.678
A12: 1979 | B12: 0.02 | C12: NA | D12: NA | E12: 0.404 | F12: 0.325 | G12: 1.982 | H12: NA | I12: 1.896 | J12: 0.497 | K12: NA | L12: 1.111 | M12: 6.235 | N12: 6.235 | O12: 0.497 | P12: 6.732
A13: 1980 | B13: 0.006 | C13: 0.229 | D13: 0.143 | E13: 0.414 | F13: 0.306 | G13: 2.007 | H13: 0.192 | I13: 0.792 | J13: 0.494 | K13: 0.102 | L13: 0.711 | M13: 5.396 | N13: 5.253 | O13: 0.599 | P13: 5.995
A14: 1981 | B14: 0.071 | C14: 0.194 | D14: 0.147 | E14: 0.29 | F14: 0.283 | G14: 1.146 | H14: 0.387 | I14: 1.982 | J14: 0.312 | K14: 0.157 | L14: 0.453 | M14: 5.422 | N14: 5.275 | O14: 0.516 | P14: 5.938
A15: 1982 | B15: 0.043 | C15: 0.29 | D15: 0.111 | E15: 0.494 | F15: 0.345 | G15: 1.558 | H15: 0.33 | I15: 3.271 | J15: 0.515 | K15: 0.061 | L15: 0.329 | M15: 7.347 | N15: 7.236 | O15: 0.344 | P15: 7.691
A16: 1983 | B16: 0.033 | C16: 0.264 | D16: 0.14 | E16: 0.446 | F16: 0.279 | G16: 1.603 | H16: 0.137 | I16: 2.352 | J16: 0.53 | K16: 0.097 | L16: 0.366 | M16: 6.247 | N16: 6.107 | O16: 0.419 | P16: 6.666
A17: 1984 | B17: 0.02 | C17: 0.206 | D17: 0.1 | E17: 0.487 | F17: 0.307 | G17: 1.722 | H17: 0.053 | I17: 1.697 | J17: 0.354 | K17: 0.04 | L17: 0.421 | M17: 5.407 | N17: 5.307 | O17: 0.429 | P17: 5.836
A18: 1985 | B18: 0.013 | C18: 0.228 | D18: 0.072 | E18: 0.471 | F18: 0.368 | G18: 1.851 | H18: 0.099 | I18: 2.774 | J18: 0.452 | K18: 0.05 | L18: 0.534 | M18: 6.912 | N18: 6.84 | O18: 0.444 | P18: 7.356
A19: 1986 | B19: 0.031 | C19: 0.194 | D19: 0.093 | E19: 0.466 | F19: 0.349 | G19: 1.189 | H19: 0.305 | I19: 2.628 | J19: 0.506 | K19: 0.16 | L19: 0.438 | M19: 6.359 | N19: 6.266 | O19: 0.703 | P19: 7.062
A20: 1987 | B20: 0.049 | C20: 0.234 | D20: 0.101 | E20: 0.205 | F20: 0.183 | G20: 1.441 | H20: 0.183 | I20: 2.251 | J20: 0.369 | K20: 0.077 | L20: 0.291 | M20: 5.384 | N20: 5.283 | O20: 0.579 | P20: 5.963
A21: 1988 | B21: 0.01 | C21: 0.353 | D21: 0.133 | E21: 0.545 | F21: 0.199 | G21: 1.119 | H21: 0.198 | I21: 3.339 | J21: 0.321 | K21: 0.099 | L21: 0.531 | M21: 6.847 | N21: 6.714 | O21: 0.701 | P21: 7.548
A22: 1989 | B22: 0.064 | C22: 0.3 | D22: 0.125 | E22: 0.443 | F22: 0.298 | G22: 1.061 | H22: 0.071 | I22: 2.126 | J22: 0.404 | K22: 0.169 | L22: 0.358 | M22: 5.419 | N22: 5.294 | O22: 0.618 | P22: 6.037
A23: 1990 | B23: 0.1 | C23: 0.268 | D23: 0.104 | E23: 0.363 | F23: 0.241 | G23: 1.259 | H23: 0.256 | I23: 3.075 | J23: 0.593 | K23: 0.123 | L23: 0.347 | M23: 6.729 | N23: 6.625 | O23: 0.466 | P23: 7.195
A24: 1991 | B24: 0.145 | C24: 0.275 | D24: 0.106 | E24: 0.495 | F24: 0.247 | G24: 1.467 | H24: 0.22 | I24: 3.282 | J24: 0.541 | K24: 0.173 | L24: 0.396 | M24: 7.347 | N24: 7.241 | O24: 0.56 | P24: 7.907
... A56: 2023 | B56: 1.432 | C56: 0.099 | D56: 1.444 | E56: 0.202 | F56: 0.093 | G56: 0.614 | H56: 0.125 | I56: 2.204 | J56: 0.209 | K56: 0.258 | L56: 0.037 | M56: 6.717 | N56: 5.273 | O56: 3.82 | P56: 10.537
A57: 2024 | B57: 1.88 | C57: 0.093 | D57: 1.317 | E57: 0.253 | F57: NA | G57: 0.414 | H57: 0.134 | I57: 3.156 | J57: 0.275 | K57: 0.301 | L57: 0.112 | M57: 7.935 | N57: 6.618 | O57: 3.134 | P57: 11.069
A58: NA = Not available. Most recent year is preliminary. Totals may not sum due to rounding. All data are expressed on a calendar-year basis.
A59: 1/ Unit of measure is pounds per person.
A60: 2/ Includes small white, cranberry, and beans classified by USDA, National Agricultural Statistics Service as other.
A61: Source: USDA, Economic Research Service.

Sheet Table 3-Plant, Harvest, Prod
A1: Table 3--U.S. vegetable and dry pulse crop industry: Total harvested area, production, and crop value | S1: =HYPERLINK("#'"&"Index'!A1","INDEX") -> INDEX
A2: Item | B2: 2008 | C2: 2009 | D2: 2010 | E2: 2011 | F2: 2012 | G2: 2013 | H2: 2014 | I2: 2015 | J2: 2016 | K2: 2017 | L2: 2018 | M2: 2019 | N2: 2020 | O2: 2021 | P2: 2022 | Q2: 2023 | R2: 2024 | S2: Percent Change 2023–24
A3: Harvested area (1,000 acres)
A4: Fresh and processing/1 | B4: 2721.064 | C4: 2733.743 | D4: 2602.885 | E4: 2478.645 | F4: 2569.285 | G4: 2484.49 | H4: 2485.63 | I4: 2454.15 | J4: 2591 | K4: 2525.03 | L4: 2463.15 | M4: 2259.9 | N4: 2271 | O4: 2271.3 | P4: 2239.7 | Q4: 2140.2 | R4: 2023.8 | S4: =(R4/Q4-1)*100 -> -5.438744
A5: Potatoes | B5: 1046.9 | C5: 1044 | D5: 1008.9 | E5: 1078.5 | F5: 1138.5 | G5: 1060.9 | H5: 1064.7 | I5: 1070.9 | J5: 1037.7 | K5: 1044.5 | L5: 1014.8 | M5: 934.3 | N5: 911.6 | O5: 929.6 | P5: 918.2 | Q5: 961.1 | R5: 925.4 | S5: =(R5/Q5-1)*100 -> -3.7144938
A6: Sweet potatoes/2 | B6: 97.3 | C6: 96.9 | D6: 116.9 | E6: 129.7 | F6: 126.6 | G6: 113 | H6: 134.6 | I6: 153.1
A7: Dry beans/3 | B7: 1363.1 | C7: 1370.1 | D7: 1698.6 | E7: 1033.4 | F7: 1484.1 | G7: 1096.4 | H7: 1436.5 | I7: 1506.1 | J7: 1238.1 | K7: 1411.7 | L7: 1181.7 | M7: 1170 | N7: 1653.8 | O7: 1320.1 | P7: 1219.2 | Q7: 1156.1 | R7: 1503.6 | S7: =(R7/Q7-1)*100 -> 30.057953
